data/sample_events.csv
timestamp_ns,event,order_id,side,price,quantity
100,ADD,1,BUY,10000,10
110,ADD,2,BUY,10000,5
120,ADD,3,SELL,10002,8
130,ADD,4,SELL,10001,6
140,MARKET,0,BUY,0,10
150,CANCEL,2,,,0
160,MARKET,0,SELL,0,7
